Workbook

Sheet Dashboard
A1: ACCOUNT DASHBOARD
A3: Starting Balance ($) | B3: 5000
A4: Fixed SL (pips) | B4: 12
A5: Default Risk % (editable) | B5: 0.005
A7: Phase1 Target (10%) | B7: =B3*0.1 -> 500
A8: Phase2 Target (5%) | B8: =B3*0.05 -> 250
A10: Daily Drawdown Limit (5%) | B10: =B3*0.05 -> 250
A11: Overall Drawdown Limit (10%) | B11: =B3*0.1 -> 500

Sheet Trade_Journal
A1: Date | B1: Session (IST) | C1: Pair | D1: Setup Type | E1: Direction | F1: Entry Price | G1: Stop Loss Price | H1: Take Profit Price | I1: Stop Loss (pips) | J1: Take Profit (pips) | K1: Lot Size | L1: Risk $ | M1: Reward $ | N1: Result $ | O1: Outcome | P1: Rule Followed? | Q1: Equity After Trade | R1: Notes
A2: ⚠️ DO NOT EDIT COLORED COLUMNS | B2: London | C2: XAUUSD | D2: Breakout retest | E2: Buy | F2: 4383 | G2: 4371 | H2: 4388 | I2: 12 | J2: 5 | K2: 0.02 | L2: =K2*100*I2 -> 24 | M2: =K2*100*J2 -> 10 | N2: =IF(O2="Win",M2,IF(O2="Loss",-L2,"")) -> 10 | O2: Win | P2: Yes | Q2: =IF(SUM(N$2:N2)="",Dashboard!B3,Dashboard!B3+SUM(N$2:N2)) -> 5010
A3: 2025-12-03 | B3: NY | C3: XAUUSD | D3: Liquidity sweep | E3: Sell | F3: 4390 | G3: 4402 | H3: 4385 | I3: 12 | J3: 5 | K3: 0.04 | L3: =K3*100*I3 -> 48 | M3: =K3*100*J3 -> 20 | N3: =IF(O3="Win",M3,IF(O3="Loss",-L3,"")) -> -48 | O3: Loss | P3: No | Q3: =IF(SUM(N$2:N3)="",Dashboard!B3,Dashboard!B3+SUM(N$2:N3)) -> 4962
A4: 2025-12-10 | B4: London | C4: XAUUSD | D4: Rejection wick | E4: Buy | F4: 4360 | G4: 4348 | H4: 4365 | I4: 12 | J4: 5 | K4: 0.02 | L4: =K4*100*I4 -> 24 | M4: =K4*100*J4 -> 10 | N4: =IF(O4="Win",M4,IF(O4="Loss",-L4,"")) -> 10 | O4: Win | P4: Yes | Q4: =IF(SUM(N$2:N4)="",Dashboard!B3,Dashboard!B3+SUM(N$2:N4)) -> 4972
L5: =K5*100*I5 -> 0 | M5: =K5*100*J5 -> 0 | N5: =IF(O5="Win",M5,IF(O5="Loss",-L5,"")) | Q5: =IF(SUM(N$2:N5)="",Dashboard!B3,Dashboard!B3+SUM(N$2:N5)) -> 4972
L6: =K6*100*I6 -> 0 | M6: =K6*100*J6 -> 0 | N6: =IF(O6="Win",M6,IF(O6="Loss",-L6,"")) | Q6: =IF(SUM(N$2:N6)="",Dashboard!B3,Dashboard!B3+SUM(N$2:N6)) -> 4972
L7: =K7*100*I7 -> 0 | M7: =K7*100*J7 -> 0 | N7: =IF(O7="Win",M7,IF(O7="Loss",-L7,"")) | Q7: =IF(SUM(N$2:N7)="",Dashboard!B3,Dashboard!B3+SUM(N$2:N7)) -> 4972
L8: =K8*100*I8 -> 0 | M8: =K8*100*J8 -> 0 | N8: =IF(O8="Win",M8,IF(O8="Loss",-L8,"")) | Q8: =IF(SUM(N$2:N8)="",Dashboard!B3,Dashboard!B3+SUM(N$2:N8)) -> 4972
L9: =K9*100*I9 -> 0 | M9: =K9*100*J9 -> 0 | N9: =IF(O9="Win",M9,IF(O9="Loss",-L9,"")) | Q9: =IF(SUM(N$2:N9)="",Dashboard!B3,Dashboard!B3+SUM(N$2:N9)) -> 4972
L10: =K10*100*I10 -> 0 | M10: =K10*100*J10 -> 0 | N10: =IF(O10="Win",M10,IF(O10="Loss",-L10,"")) | Q10: =IF(SUM(N$2:N10)="",Dashboard!B3,Dashboard!B3+SUM(N$2:N10)) -> 4972
L11: =K11*100*I11 -> 0 | M11: =K11*100*J11 -> 0 | N11: =IF(O11="Win",M11,IF(O11="Loss",-L11,"")) | Q11: =IF(SUM(N$2:N11)="",Dashboard!B3,Dashboard!B3+SUM(N$2:N11)) -> 4972
L12: =K12*100*I12 -> 0 | M12: =K12*100*J12 -> 0 | N12: =IF(O12="Win",M12,IF(O12="Loss",-L12,"")) | Q12: =IF(SUM(N$2:N12)="",Dashboard!B3,Dashboard!B3+SUM(N$2:N12)) -> 4972
L13: =K13*100*I13 -> 0 | M13: =K13*100*J13 -> 0 | N13: =IF(O13="Win",M13,IF(O13="Loss",-L13,"")) | Q13: =IF(SUM(N$2:N13)="",Dashboard!B3,Dashboard!B3+SUM(N$2:N13)) -> 4972
L14: =K14*100*I14 -> 0 | M14: =K14*100*J14 -> 0 | N14: =IF(O14="Win",M14,IF(O14="Loss",-L14,"")) | Q14: =IF(SUM(N$2:N14)="",Dashboard!B3,Dashboard!B3+SUM(N$2:N14)) -> 4972
L15: =K15*100*I15 -> 0 | M15: =K15*100*J15 -> 0 | N15: =IF(O15="Win",M15,IF(O15="Loss",-L15,"")) | Q15: =IF(SUM(N$2:N15)="",Dashboard!B3,Dashboard!B3+SUM(N$2:N15)) -> 4972
L16: =K16*100*I16 -> 0 | M16: =K16*100*J16 -> 0 | N16: =IF(O16="Win",M16,IF(O16="Loss",-L16,"")) | Q16: =IF(SUM(N$2:N16)="",Dashboard!B3,Dashboard!B3+SUM(N$2:N16)) -> 4972
L17: =K17*100*I17 -> 0 | M17: =K17*100*J17 -> 0 | N17: =IF(O17="Win",M17,IF(O17="Loss",-L17,"")) | Q17: =IF(SUM(N$2:N17)="",Dashboard!B3,Dashboard!B3+SUM(N$2:N17)) -> 4972
L18: =K18*100*I18 -> 0 | M18: =K18*100*J18 -> 0 | N18: =IF(O18="Win",M18,IF(O18="Loss",-L18,"")) | Q18: =IF(SUM(N$2:N18)="",Dashboard!B3,Dashboard!B3+SUM(N$2:N18)) -> 4972
L19: =K19*100*I19 -> 0 | M19: =K19*100*J19 -> 0 | N19: =IF(O19="Win",M19,IF(O19="Loss",-L19,"")) | Q19: =IF(SUM(N$2:N19)="",Dashboard!B3,Dashboard!B3+SUM(N$2:N19)) -> 4972
L20: =K20*100*I20 -> 0 | M20: =K20*100*J20 -> 0 | N20: =IF(O20="Win",M20,IF(O20="Loss",-L20,"")) | Q20: =IF(SUM(N$2:N20)="",Dashboard!B3,Dashboard!B3+SUM(N$2:N20)) -> 4972
L21: =K21*100*I21 -> 0 | M21: =K21*100*J21 -> 0 | N21: =IF(O21="Win",M21,IF(O21="Loss",-L21,"")) | Q21: =IF(SUM(N$2:N21)="",Dashboard!B3,Dashboard!B3+SUM(N$2:N21)) -> 4972
L22: =K22*100*I22 -> 0 | M22: =K22*100*J22 -> 0 | N22: =IF(O22="Win",M22,IF(O22="Loss",-L22,"")) | Q22: =IF(SUM(N$2:N22)="",Dashboard!B3,Dashboard!B3+SUM(N$2:N22)) -> 4972
L23: =K23*100*I23 -> 0 | M23: =K23*100*J23 -> 0 | N23: =IF(O23="Win",M23,IF(O23="Loss",-L23,"")) | Q23: =IF(SUM(N$2:N23)="",Dashboard!B3,Dashboard!B3+SUM(N$2:N23)) -> 4972
L24: =K24*100*I24 -> 0 | M24: =K24*100*J24 -> 0 | N24: =IF(O24="Win",M24,IF(O24="Loss",-L24,"")) | Q24: =IF(SUM(N$2:N24)="",Dashboard!B3,Dashboard!B3+SUM(N$2:N24)) -> 4972
L25: =K25*100*I25 -> 0 | M25: =K25*100*J25 -> 0 | N25: =IF(O25="Win",M25,IF(O25="Loss",-L25,"")) | Q25: =IF(SUM(N$2:N25)="",Dashboard!B3,Dashboard!B3+SUM(N$2:N25)) -> 4972
L26: =K26*100*I26 -> 0 | M26: =K26*100*J26 -> 0 | N26: =IF(O26="Win",M26,IF(O26="Loss",-L26,"")) | Q26: =IF(SUM(N$2:N26)="",Dashboard!B3,Dashboard!B3+SUM(N$2:N26)) -> 4972
L27: =K27*100*I27 -> 0 | M27: =K27*100*J27 -> 0 | N27: =IF(O27="Win",M27,IF(O27="Loss",-L27,"")) | Q27: =IF(SUM(N$2:N27)="",Dashboard!B3,Dashboard!B3+SUM(N$2:N27)) -> 4972
L28: =K28*100*I28 -> 0 | M28: =K28*100*J28 -> 0 | N28: =IF(O28="Win",M28,IF(O28="Loss",-L28,"")) | Q28: =IF(SUM(N$2:N28)="",Dashboard!B3,Dashboard!B3+SUM(N$2:N28)) -> 4972
L29: =K29*100*I29 -> 0 | M29: =K29*100*J29 -> 0 | N29: =IF(O29="Win",M29,IF(O29="Loss",-L29,"")) | Q29: =IF(SUM(N$2:N29)="",Dashboard!B3,Dashboard!B3+SUM(N$2:N29)) -> 4972
L30: =K30*100*I30 -> 0 | M30: =K30*100*J30 -> 0 | N30: =IF(O30="Win",M30,IF(O30="Loss",-L30,"")) | Q30: =IF(SUM(N$2:N30)="",Dashboard!B3,Dashboard!B3+SUM(N$2:N30)) -> 4972
L31: =K31*100*I31 -> 0 | M31: =K31*100*J31 -> 0 | N31: =IF(O31="Win",M31,IF(O31="Loss",-L31,"")) | Q31: =IF(SUM(N$2:N31)="",Dashboard!B3,Dashboard!B3+SUM(N$2:N31)) -> 4972
L32: =K32*100*I32 -> 0 | M32: =K32*100*J32 -> 0 | N32: =IF(O32="Win",M32,IF(O32="Loss",-L32,"")) | Q32: =IF(SUM(N$2:N32)="",Dashboard!B3,Dashboard!B3+SUM(N$2:N32)) -> 4972
L33: =K33*100*I33 -> 0 | M33: =K33*100*J33 -> 0 | N33: =IF(O33="Win",M33,IF(O33="Loss",-L33,"")) | Q33: =IF(SUM(N$2:N33)="",Dashboard!B3,Dashboard!B3+SUM(N$2:N33)) -> 4972
L34: =K34*100*I34 -> 0 | M34: =K34*100*J34 -> 0 | N34: =IF(O34="Win",M34,IF(O34="Loss",-L34,"")) | Q34: =IF(SUM(N$2:N34)="",Dashboard!B3,Dashboard!B3+SUM(N$2:N34)) -> 4972
L35: =K35*100*I35 -> 0 | M35: =K35*100*J35 -> 0 | N35: =IF(O35="Win",M35,IF(O35="Loss",-L35,"")) | Q35: =IF(SUM(N$2:N35)="",Dashboard!B3,Dashboard!B3+SUM(N$2:N35)) -> 4972
L36: =K36*100*I36 -> 0 | M36: =K36*100*J36 -> 0 | N36: =IF(O36="Win",M36,IF(O36="Loss",-L36,"")) | Q36: =IF(SUM(N$2:N36)="",Dashboard!B3,Dashboard!B3+SUM(N$2:N36)) -> 4972
L37: =K37*100*I37 -> 0 | M37: =K37*100*J37 -> 0 | N37: =IF(O37="Win",M37,IF(O37="Loss",-L37,"")) | Q37: =IF(SUM(N$2:N37)="",Dashboard!B3,Dashboard!B3+SUM(N$2:N37)) -> 4972
L38: =K38*100*I38 -> 0 | M38: =K38*100*J38 -> 0 | N38: =IF(O38="Win",M38,IF(O38="Loss",-L38,"")) | Q38: =IF(SUM(N$2:N38)="",Dashboard!B3,Dashboard!B3+SUM(N$2:N38)) -> 4972
L39: =K39*100*I39 -> 0 | M39: =K39*100*J39 -> 0 | N39: =IF(O39="Win",M39,IF(O39="Loss",-L39,"")) | Q39: =IF(SUM(N$2:N39)="",Dashboard!B3,Dashboard!B3+SUM(N$2:N39)) -> 4972
L40: =K40*100*I40 -> 0 | M40: =K40*100*J40 -> 0 | N40: =IF(O40="Win",M40,IF(O40="Loss",-L40,"")) | Q40: =IF(SUM(N$2:N40)="",Dashboard!B3,Dashboard!B3+SUM(N$2:N40)) -> 4972
...

Sheet Stats
A1: Total Trades | B1: =COUNTA(Trade_Journal!A2:A500) -> 3
A2: Winning Trades | B2: =COUNTIF(Trade_Journal!O2:O500,"Win") -> 2
A3: Losing Trades | B3: =COUNTIF(Trade_Journal!O2:O500,"Loss") -> 1
A4: Win Rate % | B4: =IF(B1=0,0,B2/B1) -> 0.66666667
A6: Total P/L ($) | B6: =SUM(Trade_Journal!N2:N500) -> -28
A7: Current Equity ($) | B7: =Dashboard!B3 + B6 -> 4972
A8: Peak Equity ($) | B8: =MAX(Trade_Journal!Q2:Q500) -> 5010
A9: Max Drawdown ($) | B9: =B8 - B7 -> 38
A10: Max Drawdown % | B10: =IF(B8=0,0,B9/B8) -> 0.0075848303

Sheet Progress
A1: Phase 1 Target (10%) | B1: =Dashboard!B7 -> 500
A2: Phase 2 Target (5%) | B2: =Dashboard!B8 -> 250
A4: Current Realized P/L ($) | B4: =Stats!B6 -> -28
A5: Progress to Phase1 (%) | B5: =MIN(1,IF(B4<=0,0,B4/B1)) -> 0
A6: Progress to Phase2 (%) | B6: =MIN(1,IF(B4<=0,0,B4/B2)) -> 0

Sheet READ ME
A1: ⚠️ READ ME FIRST – HOW TO USE THIS TRADING JOURNAL
A3: EDIT ONLY THESE COLUMNS IN Trade_Journal:
A4: Date, Session, Pair, Setup Type, Direction, Entry, SL, TP, SL pips, TP pips, Lot, Outcome, Rule Followed, Notes
A6: DO NOT EDIT:
A7: Risk $, Reward $, Result $, Equity After Trade, Stats sheet, Progress sheet
A9: HOW IT WORKS:
A10: • Risk $ = Lot × 100 × SL pips
A11: • Reward $ = Lot × 100 × TP pips
A12: • Result $ auto-calculates based on Win/Loss
A13: • Progress updates automatically toward 10% and 5% targets
A15: COLOR GUIDE:
A16: Green = Profit, Red = Loss, Yellow = Rule Broken
... A21: 3. Review Stats & Progress

Sheet 1-PAGE GUIDE
A1: XAUUSD TRADING JOURNAL – QUICK GUIDE
A3: PAIR: XAUUSD | SL: 12 pips | TP: 5 pips
A4: ACCOUNT: $10,000 | TARGET: 10% then 5%
A6: ENTER DATA ONLY IN Trade_Journal
A7: ONE ROW = ONE TRADE
A9: GREEN = WIN | RED = LOSS | YELLOW = RULE BROKEN
A11: NEVER EDIT FORMULA CELLS
A13: CHECK Stats & Progress DAILY
